Workbook
Name Slicer_Sector: #N/A

Sheet Solution 2
B3: Values
A4: Year | B4: Average of Sum of food expenses | C4: Average of Fuel and light | D4: Average of Health
A5: 2021 | B5: 2315.0639 | C5: 158.70833 | D5: 165.13333
A6: 2022 | B6: 2442.1917 | C6: 174.96944 | D6: 175.35278
A7: Grand Total | B7: 2378.6278 | C7: 166.83889 | D7: 170.24306
A18: Year | B18: Total | C18: % inflation
A19: 2017 | B19: 133.38611
A20: 2018 | B20: 138.66944 | C20: =(B20-B19)/B19 -> 0.039609321
A21: 2019 | B21: 144.12727 | C21: =(B21-B20)/B20 -> 0.03935855
A22: 2020 | B22: 153.33 | C22: =(B22-B21)/B21 -> 0.063851394
A23: 2021 | B23: 161.41667 | C23: =(B23-B22)/B22 -> 0.052740277
A24: 2022 | B24: 172.075 | C24: =(B24-B23)/B23 -> 0.066029943
A25: 2023 | B25: 177.57333 | C25: =(B25-B24)/B24 -> 0.031953121
F42: 2015

Sheet Consumer price index
A1: Sector | B1: Year | C1: Month | D1: Short Date | E1: Cereals and products | F1: Meat and fish | G1: Egg | H1: Milk and products | I1: Oils and fats | J1: Fruits | K1: Vegetables | L1: Pulses and products | M1: Sugar and Confectionery | N1: Spices | O1: Non-alcoholic beverages | P1: Prepared meals, snacks, sweets etc. | Q1: Food and beverages | R1: Pan, tobacco and intoxicants | S1: Clothing | T1: Footwear | U1: Clothing and footwear | V1: Housing | W1: Fuel and light | X1: Household goods and services | Y1: Health | Z1: Transport and communication | AA1: Recreation and amusement | AB1: Education | AC1: Personal care and effects | AD1: Miscellaneous | AE1: General index | AF1: Average food expense | AG1: Average Housing Expense | AH1: Average Other Expenses | AI1: Sum of food expenses | AJ1: Sum of Housing Exp | AK1: Sum of clothing | AL1: Sum of others | AM1: Total Expenses
A2: Rural | B2: 2013 | C2: January | D2: =TEXT(DATE(B2, MONTH(1&C2), 1), "mmm-yy") -> Jan-13 | E2: 107.5 | F2: 106.3 | G2: 108.1 | H2: 104.9 | I2: 106.1 | J2: 103.9 | K2: 101.9 | L2: 106.1 | M2: 106.8 | N2: 103.1 | O2: 104.8 | P2: 106.7 | Q2: 105.5 | R2: 105.1 | S2: 106.5 | T2: 105.8 | U2: 106.4 | V2: ='Handle Missing Value Sheet only'!$F$5 -> 139.27097 | W2: 105.5 | X2: 104.8 | Y2: 104 | Z2: 103.3 | AA2: 103.4 | AB2: 103.8 | AC2: 104.7 | AD2: 104 | AE2: 105.1 | AF2: =AVERAGE(All_India_Index_Upto_April23__1___1[[#This Row],[Cereals and products]:[Pan, tobacco and intoxicants]]) -> 105.48571 | AG2: =AVERAGE(All_India_Index_Upto_April23__1___1[[#This Row],[Household goods and services]],All_India_Index_Upto_April23__1___1[[#This Row],[Housing]]) -> 122.03548 | AH2: =AVERAGE(All_India_Index_Upto_April23__1___1[[#This Row],[Miscellaneous]],All_India_Index_Upto_April23__1___1[[#This Row],[Personal care and effects]],All_India_Index_Upto_April23__1___1[[#This Row],[Education]],All_India_Index_Upto_April23__1___1[[#This Row],[Recreation and amusement]]) -> 103.975 | AI2: =SUM(All_India_Index_Upto_April23__1___1[[#This Row],[Cereals and products]:[Pan, tobacco and intoxicants]]) -> 1476.8 | AJ2: =SUM(All_India_Index_Upto_April23__1___1[[#This Row],[Household goods and services]],All_India_Index_Upto_April23__1___1[[#This Row],[Housing]]) -> 244.07097 | AK2: =All_India_Index_Upto_April23__1___1[[#This Row],[Clothing]]+All_India_Index_Upto_April23__1___1[[#This Row],[Footwear]] -> 212.3 | AL2: =All_India_Index_Upto_April23__1___1[[#This Row],[Miscellaneous]]+All_India_Index_Upto_April23__1___1[[#This Row],[Personal care and effects]]+All_India_Index_Upto_April23__1___1[[#This Row],[Education]]+All_India_Index_Upto_April23__1___1[[#This Row],[Recreation and amusement]] -> 415.9 | AM2: =SUM(All_India_Index_Upto_April23__1___1[[#This Row],[Sum of others]],All_India_Index_Upto_April23__1___1[[#This Row],[Sum of clothing]],All_India_Index_Upto_April23__1___1[[#This Row],[Sum of Housing Exp]],All_India_Index_Upto_April23__1___1[[#This Row],[Sum of food expenses]],All_India_Index_Upto_April23__1___1[[#This Row],[Transport and communication]],All_India_Index_Upto_April23__1___1[[#This Row],[Health]],All_India_Index_Upto_April23__1___1[[#This Row],[Fuel and light]]) -> 2661.871
A3: Urban | B3: 2013 | C3: January | D3: =TEXT(DATE(B3, MONTH(1&C3), 1), "mmm-yy") -> Jan-13 | E3: 110.5 | F3: 109.1 | G3: 113 | H3: 103.6 | I3: 103.4 | J3: 102.3 | K3: 102.9 | L3: 105.8 | M3: 105.1 | N3: 101.8 | O3: 105.1 | P3: 107.9 | Q3: 105.9 | R3: 105.2 | S3: 105.9 | T3: 105 | U3: 105.8 | V3: 100.3 | W3: 105.4 | X3: 104.8 | Y3: 104.1 | Z3: 103.2 | AA3: 102.9 | AB3: 103.5 | AC3: 104.3 | AD3: 103.7 | AE3: 104 | AF3: =AVERAGE(All_India_Index_Upto_April23__1___1[[#This Row],[Cereals and products]:[Pan, tobacco and intoxicants]]) -> 105.82857 | AG3: =AVERAGE(All_India_Index_Upto_April23__1___1[[#This Row],[Household goods and services]],All_India_Index_Upto_April23__1___1[[#This Row],[Housing]]) -> 102.55 | AH3: =AVERAGE(All_India_Index_Upto_April23__1___1[[#This Row],[Miscellaneous]],All_India_Index_Upto_April23__1___1[[#This Row],[Personal care and effects]],All_India_Index_Upto_April23__1___1[[#This Row],[Education]],All_India_Index_Upto_April23__1___1[[#This Row],[Recreation and amusement]]) -> 103.6 | AI3: =SUM(All_India_Index_Upto_April23__1___1[[#This Row],[Cereals and products]:[Pan, tobacco and intoxicants]]) -> 1481.6 | AJ3: =SUM(All_India_Index_Upto_April23__1___1[[#This Row],[Household goods and services]],All_India_Index_Upto_April23__1___1[[#This Row],[Housing]]) -> 205.1 | AK3: =All_India_Index_Upto_April23__1___1[[#This Row],[Clothing]]+All_India_Index_Upto_April23__1___1[[#This Row],[Footwear]] -> 210.9 | AL3: =All_India_Index_Upto_April23__1___1[[#This Row],[Miscellaneous]]+All_India_Index_Upto_April23__1___1[[#This Row],[Personal care and effects]]+All_India_Index_Upto_April23__1___1[[#This Row],[Education]]+All_India_Index_Upto_April23__1___1[[#This Row],[Recreation and amusement]] -> 414.4 | AM3: =SUM(All_India_Index_Upto_April23__1___1[[#This Row],[Sum of others]],All_India_Index_Upto_April23__1___1[[#This Row],[Sum of clothing]],All_India_Index_Upto_April23__1___1[[#This Row],[Sum of Housing Exp]],All_India_Index_Upto_April23__1___1[[#This Row],[Sum of food expenses]],All_India_Index_Upto_April23__1___1[[#This Row],[Transport and communication]],All_India_Index_Upto_April23__1___1[[#This Row],[Health]],All_India_Index_Upto_April23__1___1[[#This Row],[Fuel and light]]) -> 2624.7
A4: Rural+Urban | B4: 2013 | C4: January | D4: =TEXT(DATE(B4, MONTH(1&C4), 1), "mmm-yy") -> Jan-13 | E4: 108.4 | F4: 107.3 | G4: 110 | H4: 104.4 | I4: 105.1 | J4: 103.2 | K4: 102.2 | L4: 106 | M4: 106.2 | N4: 102.7 | O4: 104.9 | P4: 107.3 | Q4: 105.6 | R4: 105.1 | S4: 106.3 | T4: 105.5 | U4: 106.2 | V4: 100.3 | W4: 105.5 | X4: 104.8 | Y4: 104 | Z4: 103.2 | AA4: 103.1 | AB4: 103.6 | AC4: 104.5 | AD4: 103.9 | AE4: 104.6 | AF4: =AVERAGE(All_India_Index_Upto_April23__1___1[[#This Row],[Cereals and products]:[Pan, tobacco and intoxicants]]) -> 105.6 | AG4: =AVERAGE(All_India_Index_Upto_April23__1___1[[#This Row],[Household goods and services]],All_India_Index_Upto_April23__1___1[[#This Row],[Housing]]) -> 102.55 | AH4: =AVERAGE(All_India_Index_Upto_April23__1___1[[#This Row],[Miscellaneous]],All_India_Index_Upto_April23__1___1[[#This Row],[Personal care and effects]],All_India_Index_Upto_April23__1___1[[#This Row],[Education]],All_India_Index_Upto_April23__1___1[[#This Row],[Recreation and amusement]]) -> 103.775 | AI4: =SUM(All_India_Index_Upto_April23__1___1[[#This Row],[Cereals and products]:[Pan, tobacco and intoxicants]]) -> 1478.4 | AJ4: =SUM(All_India_Index_Upto_April23__1___1[[#This Row],[Household goods and services]],All_India_Index_Upto_April23__1___1[[#This Row],[Housing]]) -> 205.1 | AK4: =All_India_Index_Upto_April23__1___1[[#This Row],[Clothing]]+All_India_Index_Upto_April23__1___1[[#This Row],[Footwear]] -> 211.8 | AL4: =All_India_Index_Upto_April23__1___1[[#This Row],[Miscellaneous]]+All_India_Index_Upto_April23__1___1[[#This Row],[Personal care and effects]]+All_India_Index_Upto_April23__1___1[[#This Row],[Education]]+All_India_Index_Upto_April23__1___1[[#This Row],[Recreation and amusement]] -> 415.1 | AM4: =SUM(All_India_Index_Upto_April23__1___1[[#This Row],[Sum of others]],All_India_Index_Upto_April23__1___1[[#This Row],[Sum of clothing]],All_India_Index_Upto_April23__1___1[[#This Row],[Sum of Housing Exp]],All_India_Index_Upto_April23__1___1[[#This Row],[Sum of food expenses]],All_India_Index_Upto_April23__1___1[[#This Row],[Transport and communication]],All_India_Index_Upto_April23__1___1[[#This Row],[Health]],All_India_Index_Upto_April23__1___1[[#This Row],[Fuel and light]]) -> 2623.1
A5: Rural | B5: 2013 | C5: February | D5: =TEXT(DATE(B5, MONTH(1&C5), 1), "mmm-yy") -> Feb-13 | E5: 109.2 | F5: 108.7 | G5: 110.2 | H5: 105.4 | I5: 106.7 | J5: 104 | K5: 102.4 | L5: 105.9 | M5: 105.7 | N5: 103.1 | O5: 105.1 | P5: 107.7 | Q5: 106.3 | R5: 105.6 | S5: 107.1 | T5: 106.3 | U5: 107 | V5: ='Handle Missing Value Sheet only'!$F$5 -> 139.27097 | W5: 106.2 | X5: 105.2 | Y5: 104.4 | Z5: 103.9 | AA5: 104 | AB5: 104.1 | AC5: 104.6 | AD5: 104.4 | AE5: 105.8 | AF5: =AVERAGE(All_India_Index_Upto_April23__1___1[[#This Row],[Cereals and products]:[Pan, tobacco and intoxicants]]) -> 106.14286 | AG5: =AVERAGE(All_India_Index_Upto_April23__1___1[[#This Row],[Household goods and services]],All_India_Index_Upto_April23__1___1[[#This Row],[Housing]]) -> 122.23548 | AH5: =AVERAGE(All_India_Index_Upto_April23__1___1[[#This Row],[Miscellaneous]],All_India_Index_Upto_April23__1___1[[#This Row],[Personal care and effects]],All_India_Index_Upto_April23__1___1[[#This Row],[Education]],All_India_Index_Upto_April23__1___1[[#This Row],[Recreation and amusement]]) -> 104.275 | AI5: =SUM(All_India_Index_Upto_April23__1___1[[#This Row],[Cereals and products]:[Pan, tobacco and intoxicants]]) -> 1486 | AJ5: =SUM(All_India_Index_Upto_April23__1___1[[#This Row],[Household goods and services]],All_India_Index_Upto_April23__1___1[[#This Row],[Housing]]) -> 244.47097 | AK5: =All_India_Index_Upto_April23__1___1[[#This Row],[Clothing]]+All_India_Index_Upto_April23__1___1[[#This Row],[Footwear]] -> 213.4 | AL5: =All_India_Index_Upto_April23__1___1[[#This Row],[Miscellaneous]]+All_India_Index_Upto_April23__1___1[[#This Row],[Personal care and effects]]+All_India_Index_Upto_April23__1___1[[#This Row],[Education]]+All_India_Index_Upto_April23__1___1[[#This Row],[Recreation and amusement]] -> 417.1 | AM5: =SUM(All_India_Index_Upto_April23__1___1[[#This Row],[Sum of others]],All_India_Index_Upto_April23__1___1[[#This Row],[Sum of clothing]],All_India_Index_Upto_April23__1___1[[#This Row],[Sum of Housing Exp]],All_India_Index_Upto_April23__1___1[[#This Row],[Sum of food expenses]],All_India_Index_Upto_April23__1___1[[#This Row],[Transport and communication]],All_India_Index_Upto_April23__1___1[[#This Row],[Health]],All_India_Index_Upto_April23__1___1[[#This Row],[Fuel and light]]) -> 2675.471
A6: Urban | B6: 2013 | C6: February | D6: =TEXT(DATE(B6, MONTH(1&C6), 1), "mmm-yy") -> Feb-13 | E6: 112.9 | F6: 112.9 | G6: 116.9 | H6: 104 | I6: 103.5 | J6: 103.1 | K6: 104.9 | L6: 104.1 | M6: 103.8 | N6: 102.3 | O6: 106 | P6: 109 | Q6: 107.2 | R6: 106 | S6: 106.6 | T6: 105.5 | U6: 106.4 | V6: 100.4 | W6: 105.7 | X6: 105.2 | Y6: 104.7 | Z6: 104.4 | AA6: 103.3 | AB6: 103.7 | AC6: 104.3 | AD6: 104.3 | AE6: 104.7 | AF6: =AVERAGE(All_India_Index_Upto_April23__1___1[[#This Row],[Cereals and products]:[Pan, tobacco and intoxicants]]) -> 106.9 | AG6: =AVERAGE(All_India_Index_Upto_April23__1___1[[#This Row],[Household goods and services]],All_India_Index_Upto_April23__1___1[[#This Row],[Housing]]) -> 102.8 | AH6: =AVERAGE(All_India_Index_Upto_April23__1___1[[#This Row],[Miscellaneous]],All_India_Index_Upto_April23__1___1[[#This Row],[Personal care and effects]],All_India_Index_Upto_April23__1___1[[#This Row],[Education]],All_India_Index_Upto_April23__1___1[[#This Row],[Recreation and amusement]]) -> 103.9 | AI6: =SUM(All_India_Index_Upto_April23__1___1[[#This Row],[Cereals and products]:[Pan, tobacco and intoxicants]]) -> 1496.6 | AJ6: =SUM(All_India_Index_Upto_April23__1___1[[#This Row],[Household goods and services]],All_India_Index_Upto_April23__1___1[[#This Row],[Housing]]) -> 205.6 | AK6: =All_India_Index_Upto_April23__1___1[[#This Row],[Clothing]]+All_India_Index_Upto_April23__1___1[[#This Row],[Footwear]] -> 212.1 | AL6: =All_India_Index_Upto_April23__1___1[[#This Row],[Miscellaneous]]+All_India_Index_Upto_April23__1___1[[#This Row],[Personal care and effects]]+All_India_Index_Upto_April23__1___1[[#This Row],[Education]]+All_India_Index_Upto_April23__1___1[[#This Row],[Recreation and amusement]] -> 415.6 | AM6: =SUM(All_India_Index_Upto_April23__1___1[[#This Row],[Sum of others]],All_India_Index_Upto_April23__1___1[[#This Row],[Sum of clothing]],All_India_Index_Upto_April23__1___1[[#This Row],[Sum of Housing Exp]],All_India_Index_Upto_April23__1___1[[#This Row],[Sum of food expenses]],All_India_Index_Upto_April23__1___1[[#This Row],[Transport and communication]],All_India_Index_Upto_April23__1___1[[#This Row],[Health]],All_India_Index_Upto_April23__1___1[[#This Row],[Fuel and light]]) -> 2644.7
A7: Rural+Urban | B7: 2013 | C7: February | D7: =TEXT(DATE(B7, MONTH(1&C7), 1), "mmm-yy") -> Feb-13 | E7: 110.4 | F7: 110.2 | G7: 112.8 | H7: 104.9 | I7: 105.5 | J7: 103.6 | K7: 103.2 | L7: 105.3 | M7: 105.1 | N7: 102.8 | O7: 105.5 | P7: 108.3 | Q7: 106.6 | R7: 105.7 | S7: 106.9 | T7: 106 | U7: 106.8 | V7: 100.4 | W7: 106 | X7: 105.2 | Y7: 104.5 | Z7: 104.2 | AA7: 103.6 | AB7: 103.9 | AC7: 104.5 | AD7: 104.4 | AE7: 105.3 | AF7: =AVERAGE(All_India_Index_Upto_April23__1___1[[#This Row],[Cereals and products]:[Pan, tobacco and intoxicants]]) -> 106.42143 | AG7: =AVERAGE(All_India_Index_Upto_April23__1___1[[#This Row],[Household goods and services]],All_India_Index_Upto_April23__1___1[[#This Row],[Housing]]) -> 102.8 | AH7: =AVERAGE(All_India_Index_Upto_April23__1___1[[#This Row],[Miscellaneous]],All_India_Index_Upto_April23__1___1[[#This Row],[Personal care and effects]],All_India_Index_Upto_April23__1___1[[#This Row],[Education]],All_India_Index_Upto_April23__1___1[[#This Row],[Recreation and amusement]]) -> 104.1 | AI7: =SUM(All_India_Index_Upto_April23__1___1[[#This Row],[Cereals and products]:[Pan, tobacco and intoxicants]]) -> 1489.9 | AJ7: =SUM(All_India_Index_Upto_April23__1___1[[#This Row],[Household goods and services]],All_India_Index_Upto_April23__1___1[[#This Row],[Housing]]) -> 205.6 | AK7: =All_India_Index_Upto_April23__1___1[[#This Row],[Clothing]]+All_India_Index_Upto_April23__1___1[[#This Row],[Footwear]] -> 212.9 | AL7: =All_India_Index_Upto_April23__1___1[[#This Row],[Miscellaneous]]+All_India_Index_Upto_April23__1___1[[#This Row],[Personal care and effects]]+All_India_Index_Upto_April23__1___1[[#This Row],[Education]]+All_India_Index_Upto_April23__1___1[[#This Row],[Recreation and amusement]] -> 416.4 | AM7: =SUM(All_India_Index_Upto_April23__1___1[[#This Row],[Sum of others]],All_India_Index_Upto_April23__1___1[[#This Row],[Sum of clothing]],All_India_Index_Upto_April23__1___1[[#This Row],[Sum of Housing Exp]],All_India_Index_Upto_April23__1___1[[#This Row],[Sum of food expenses]],All_India_Index_Upto_April23__1___1[[#This Row],[Transport and communication]],All_India_Index_Upto_April23__1___1[[#This Row],[Health]],All_India_Index_Upto_April23__1___1[[#This Row],[Fuel and light]]) -> 2639.5
A8: Rural | B8: 2013 | C8: March | D8: =TEXT(DATE(B8, MONTH(1&C8), 1), "mmm-yy") -> Mar-13 | E8: 110.2 | F8: 108.8 | G8: 109.9 | H8: 105.6 | I8: 106.2 | J8: 105.7 | K8: 101.4 | L8: 105.7 | M8: 105 | N8: 103.3 | O8: 105.6 | P8: 108.2 | Q8: 106.6 | R8: 106.5 | S8: 107.6 | T8: 106.8 | U8: 107.5 | V8: ='Handle Missing Value Sheet only'!$F$5 -> 139.27097 | W8: 106.1 | X8: 105.6 | Y8: 104.7 | Z8: 104.6 | AA8: 104 | AB8: 104.3 | AC8: 104.3 | AD8: 104.6 | AE8: 106 | AF8: =AVERAGE(All_India_Index_Upto_April23__1___1[[#This Row],[Cereals and products]:[Pan, tobacco and intoxicants]]) -> 106.33571 | AG8: =AVERAGE(All_India_Index_Upto_April23__1___1[[#This Row],[Household goods and services]],All_India_Index_Upto_April23__1___1[[#This Row],[Housing]]) -> 122.43548 | AH8: =AVERAGE(All_India_Index_Upto_April23__1___1[[#This Row],[Miscellaneous]],All_India_Index_Upto_April23__1___1[[#This Row],[Personal care and effects]],All_India_Index_Upto_April23__1___1[[#This Row],[Education]],All_India_Index_Upto_April23__1___1[[#This Row],[Recreation and amusement]]) -> 104.3 | AI8: =SUM(All_India_Index_Upto_April23__1___1[[#This Row],[Cereals and products]:[Pan, tobacco and intoxicants]]) -> 1488.7 | AJ8: =SUM(All_India_Index_Upto_April23__1___1[[#This Row],[Household goods and services]],All_India_Index_Upto_April23__1___1[[#This Row],[Housing]]) -> 244.87097 | AK8: =All_India_Index_Upto_April23__1___1[[#This Row],[Clothing]]+All_India_Index_Upto_April23__1___1[[#This Row],[Footwear]] -> 214.4 | AL8: =All_India_Index_Upto_April23__1___1[[#This Row],[Miscellaneous]]+All_India_Index_Upto_April23__1___1[[#This Row],[Personal care and effects]]+All_India_Index_Upto_April23__1___1[[#This Row],[Education]]+All_India_Index_Upto_April23__1___1[[#This Row],[Recreation and amusement]] -> 417.2 | AM8: =SUM(All_India_Index_Upto_April23__1___1[[#This Row],[Sum of others]],All_India_Index_Upto_April23__1___1[[#This Row],[Sum of clothing]],All_India_Index_Upto_April23__1___1[[#This Row],[Sum of Housing Exp]],All_India_Index_Upto_April23__1___1[[#This Row],[Sum of food expenses]],All_India_Index_Upto_April23__1___1[[#This Row],[Transport and communication]],All_India_Index_Upto_April23__1___1[[#This Row],[Health]],All_India_Index_Upto_April23__1___1[[#This Row],[Fuel and light]]) -> 2680.571
A9: Urban | B9: 2013 | C9: March | D9: =TEXT(DATE(B9, MONTH(1&C9), 1), "mmm-yy") -> Mar-13 | E9: 113.9 | F9: 111.4 | G9: 113.2 | H9: 104.3 | I9: 102.7 | J9: 104.9 | K9: 103.8 | L9: 103.5 | M9: 102.6 | N9: 102.4 | O9: 107 | P9: 109.8 | Q9: 107.3 | R9: 106.8 | S9: 107.2 | T9: 106 | U9: 107 | V9: 100.4 | W9: 106 | X9: 105.7 | Y9: 105.2 | Z9: 105.5 | AA9: 103.5 | AB9: 103.8 | AC9: 104.2 | AD9: 104.9 | AE9: 105 | AF9: =AVERAGE(All_India_Index_Upto_April23__1___1[[#This Row],[Cereals and products]:[Pan, tobacco and intoxicants]]) -> 106.68571 | AG9: =AVERAGE(All_India_Index_Upto_April23__1___1[[#This Row],[Household goods and services]],All_India_Index_Upto_April23__1___1[[#This Row],[Housing]]) -> 103.05 | AH9: =AVERAGE(All_India_Index_Upto_April23__1___1[[#This Row],[Miscellaneous]],All_India_Index_Upto_April23__1___1[[#This Row],[Personal care and effects]],All_India_Index_Upto_April23__1___1[[#This Row],[Education]],All_India_Index_Upto_April23__1___1[[#This Row],[Recreation and amusement]]) -> 104.1 | AI9: =SUM(All_India_Index_Upto_April23__1___1[[#This Row],[Cereals and products]:[Pan, tobacco and intoxicants]]) -> 1493.6 | AJ9: =SUM(All_India_Index_Upto_April23__1___1[[#This Row],[Household goods and services]],All_India_Index_Upto_April23__1___1[[#This Row],[Housing]]) -> 206.1 | AK9: =All_India_Index_Upto_April23__1___1[[#This Row],[Clothing]]+All_India_Index_Upto_April23__1___1[[#This Row],[Footwear]] -> 213.2 | AL9: =All_India_Index_Upto_April23__1___1[[#This Row],[Miscellaneous]]+All_India_Index_Upto_April23__1___1[[#This Row],[Personal care and effects]]+All_India_Index_Upto_April23__1___1[[#This Row],[Education]]+All_India_Index_Upto_April23__1___1[[#This Row],[Recreation and amusement]] -> 416.4 | AM9: =SUM(All_India_Index_Upto_April23__1___1[[#This Row],[Sum of others]],All_India_Index_Upto_April23__1___1[[#This Row],[Sum of clothing]],All_India_Index_Upto_April23__1___1[[#This Row],[Sum of Housing Exp]],All_India_Index_Upto_April23__1___1[[#This Row],[Sum of food expenses]],All_India_Index_Upto_April23__1___1[[#This Row],[Transport and communication]],All_India_Index_Upto_April23__1___1[[#This Row],[Health]],All_India_Index_Upto_April23__1___1[[#This Row],[Fuel and light]]) -> 2646
A10: Rural+Urban | B10: 2013 | C10: March | D10: =TEXT(DATE(B10, MONTH(1&C10), 1), "mmm-yy") -> Mar-13 | E10: 111.4 | F10: 109.7 | G10: 111.2 | H10: 105.1 | I10: 104.9 | J10: 105.3 | K10: 102.2 | L10: 105 | M10: 104.2 | N10: 103 | O10: 106.2 | P10: 108.9 | Q10: 106.9 | R10: 106.6 | S10: 107.4 | T10: 106.5 | U10: 107.3 | V10: 100.4 | W10: 106.1 | X10: 105.6 | Y10: 104.9 | Z10: 105.1 | AA10: 103.7 | AB10: 104 | AC10: 104.3 | AD10: 104.7 | AE10: 105.5 | AF10: =AVERAGE(All_India_Index_Upto_April23__1___1[[#This Row],[Cereals and products]:[Pan, tobacco and intoxicants]]) -> 106.47143 | AG10: =AVERAGE(All_India_Index_Upto_April23__1___1[[#This Row],[Household goods and services]],All_India_Index_Upto_April23__1___1[[#This Row],[Housing]]) -> 103 | AH10: =AVERAGE(All_India_Index_Upto_April23__1___1[[#This Row],[Miscellaneous]],All_India_Index_Upto_April23__1___1[[#This Row],[Personal care and effects]],All_India_Index_Upto_April23__1___1[[#This Row],[Education]],All_India_Index_Upto_April23__1___1[[#This Row],[Recreation and amusement]]) -> 104.175 | AI10: =SUM(All_India_Index_Upto_April23__1___1[[#This Row],[Cereals and products]:[Pan, tobacco and intoxicants]]) -> 1490.6 | AJ10: =SUM(All_India_Index_Upto_April23__1___1[[#This Row],[Household goods and services]],All_India_Index_Upto_April23__1___1[[#This Row],[Housing]]) -> 206 | AK10: =All_India_Index_Upto_April23__1___1[[#This Row],[Clothing]]+All_India_Index_Upto_April23__1___1[[#This Row],[Footwear]] -> 213.9 | AL10: =All_India_Index_Upto_April23__1___1[[#This Row],[Miscellaneous]]+All_India_Index_Upto_April23__1___1[[#This Row],[Personal care and effects]]+All_India_Index_Upto_April23__1___1[[#This Row],[Education]]+All_India_Index_Upto_April23__1___1[[#This Row],[Recreation and amusement]] -> 416.7 | AM10: =SUM(All_India_Index_Upto_April23__1___1[[#This Row],[Sum of others]],All_India_Index_Upto_April23__1___1[[#This Row],[Sum of clothing]],All_India_Index_Upto_April23__1___1[[#This Row],[Sum of Housing Exp]],All_India_Index_Upto_April23__1___1[[#This Row],[Sum of food expenses]],All_India_Index_Upto_April23__1___1[[#This Row],[Transport and communication]],All_India_Index_Upto_April23__1___1[[#This Row],[Health]],All_India_Index_Upto_April23__1___1[[#This Row],[Fuel and light]]) -> 2643.3
A11: Rural | B11: 2013 | C11: April | D11: =TEXT(DATE(B11, MONTH(1&C11), 1), "mmm-yy") -> Apr-13 | E11: 110.2 | F11: 109.5 | G11: 106.9 | H11: 106.3 | I11: 105.7 | J11: 108.3 | K11: 103.4 | L11: 105.7 | M11: 104.2 | N11: 103.2 | O11: 106.5 | P11: 108.8 | Q11: 107.1 | R11: 107.1 | S11: 108.1 | T11: 107.4 | U11: 108 | V11: ='Handle Missing Value Sheet only'!$F$5 -> 139.27097 | W11: 106.5 | X11: 106.1 | Y11: 105.1 | Z11: 104.4 | AA11: 104.5 | AB11: 104.8 | AC11: 102.7 | AD11: 104.6 | AE11: 106.4 | AF11: =AVERAGE(All_India_Index_Upto_April23__1___1[[#This Row],[Cereals and products]:[Pan, tobacco and intoxicants]]) -> 106.63571 | AG11: =AVERAGE(All_India_Index_Upto_April23__1___1[[#This Row],[Household goods and services]],All_India_Index_Upto_April23__1___1[[#This Row],[Housing]]) -> 122.68548 | AH11: =AVERAGE(All_India_Index_Upto_April23__1___1[[#This Row],[Miscellaneous]],All_India_Index_Upto_April23__1___1[[#This Row],[Personal care and effects]],All_India_Index_Upto_April23__1___1[[#This Row],[Education]],All_India_Index_Upto_April23__1___1[[#This Row],[Recreation and amusement]]) -> 104.15 | AI11: =SUM(All_India_Index_Upto_April23__1___1[[#This Row],[Cereals and products]:[Pan, tobacco and intoxicants]]) -> 1492.9 | AJ11: =SUM(All_India_Index_Upto_April23__1___1[[#This Row],[Household goods and services]],All_India_Index_Upto_April23__1___1[[#This Row],[Housing]]) -> 245.37097 | AK11: =All_India_Index_Upto_April23__1___1[[#This Row],[Clothing]]+All_India_Index_Upto_April23__1___1[[#This Row],[Footwear]] -> 215.5 | AL11: =All_India_Index_Upto_April23__1___1[[#This Row],[Miscellaneous]]+All_India_Index_Upto_April23__1___1[[#This Row],[Personal care and effects]]+All_India_Index_Upto_April23__1___1[[#This Row],[Education]]+All_India_Index_Upto_April23__1___1[[#This Row],[Recreation and amusement]] -> 416.6 | AM11: =SUM(All_India_Index_Upto_April23__1___1[[#This Row],[Sum of others]],All_India_Index_Upto_April23__1___1[[#This Row],[Sum of clothing]],All_India_Index_Upto_April23__1___1[[#This Row],[Sum of Housing Exp]],All_India_Index_Upto_April23__1___1[[#This Row],[Sum of food expenses]],All_India_Index_Upto_April23__1___1[[#This Row],[Transport and communication]],All_India_Index_Upto_April23__1___1[[#This Row],[Health]],All_India_Index_Upto_April23__1___1[[#This Row],[Fuel and light]]) -> 2686.371
A12: Urban | B12: 2013 | C12: April | D12: =TEXT(DATE(B12, MONTH(1&C12), 1), "mmm-yy") -> Apr-13 | E12: 114.6 | F12: 113.4 | G12: 106 | H12: 104.7 | I12: 102.1 | J12: 109.5 | K12: 109.7 | L12: 104.6 | M12: 102 | N12: 103.5 | O12: 108.2 | P12: 110.6 | Q12: 108.8 | R12: 108.5 | S12: 107.9 | T12: 106.4 | U12: 107.7 | V12: 100.5 | W12: 106.4 | X12: 106.5 | Y12: 105.7 | Z12: 105 | AA12: 104 | AB12: 105.2 | AC12: 103.2 | AD12: 105.1 | AE12: 105.7 | AF12: =AVERAGE(All_India_Index_Upto_April23__1___1[[#This Row],[Cereals and products]:[Pan, tobacco and intoxicants]]) -> 107.58571 | AG12: =AVERAGE(All_India_Index_Upto_April23__1___1[[#This Row],[Household goods and services]],All_India_Index_Upto_April23__1___1[[#This Row],[Housing]]) -> 103.5 | AH12: =AVERAGE(All_India_Index_Upto_April23__1___1[[#This Row],[Miscellaneous]],All_India_Index_Upto_April23__1___1[[#This Row],[Personal care and effects]],All_India_Index_Upto_April23__1___1[[#This Row],[Education]],All_India_Index_Upto_April23__1___1[[#This Row],[Recreation and amusement]]) -> 104.375 | AI12: =SUM(All_India_Index_Upto_April23__1___1[[#This Row],[Cereals and products]:[Pan, tobacco and intoxicants]]) -> 1506.2 | AJ12: =SUM(All_India_Index_Upto_April23__1___1[[#This Row],[Household goods and services]],All_India_Index_Upto_April23__1___1[[#This Row],[Housing]]) -> 207 | AK12: =All_India_Index_Upto_April23__1___1[[#This Row],[Clothing]]+All_India_Index_Upto_April23__1___1[[#This Row],[Footwear]] -> 214.3 | AL12: =All_India_Index_Upto_April23__1___1[[#This Row],[Miscellaneous]]+All_India_Index_Upto_April23__1___1[[#This Row],[Personal care and effects]]+All_India_Index_Upto_April23__1___1[[#This Row],[Education]]+All_India_Index_Upto_April23__1___1[[#This Row],[Recreation and amusement]] -> 417.5 | AM12: =SUM(All_India_Index_Upto_April23__1___1[[#This Row],[Sum of others]],All_India_Index_Upto_April23__1___1[[#This Row],[Sum of clothing]],All_India_Index_Upto_April23__1___1[[#This Row],[Sum of Housing Exp]],All_India_Index_Upto_April23__1___1[[#This Row],[Sum of food expenses]],All_India_Index_Upto_April23__1___1[[#This Row],[Transport and communication]],All_India_Index_Upto_April23__1___1[[#This Row],[Health]],All_India_Index_Upto_April23__1___1[[#This Row],[Fuel and light]]) -> 2662.1
A13: Rural+Urban | B13: 2013 | C13: April | D13: =TEXT(DATE(B13, MONTH(1&C13), 1), "mmm-yy") -> Apr-13 | E13: 111.6 | F13: 110.9 | G13: 106.6 | H13: 105.7 | I13: 104.4 | J13: 108.9 | K13: 105.5 | L13: 105.3 | M13: 103.5 | N13: 103.3 | O13: 107.2 | P13: 109.6 | Q13: 107.7 | R13: 107.5 | S13: 108 | T13: 107 | U13: 107.9 | V13: 100.5 | W13: 106.5 | X13: 106.3 | Y13: 105.3 | Z13: 104.7 | AA13: 104.2 | AB13: 105 | AC13: 102.9 | AD13: 104.8 | AE13: 106.1 | AF13: =AVERAGE(All_India_Index_Upto_April23__1___1[[#This Row],[Cereals and products]:[Pan, tobacco and intoxicants]]) -> 106.97857 | AG13: =AVERAGE(All_India_Index_Upto_April23__1___1[[#This Row],[Household goods and services]],All_India_Index_Upto_April23__1___1[[#This Row],[Housing]]) -> 103.4 | AH13: =AVERAGE(All_India_Index_Upto_April23__1___1[[#This Row],[Miscellaneous]],All_India_Index_Upto_April23__1___1[[#This Row],[Personal care and effects]],All_India_Index_Upto_April23__1___1[[#This Row],[Education]],All_India_Index_Upto_April23__1___1[[#This Row],[Recreation and amusement]]) -> 104.225 | AI13: =SUM(All_India_Index_Upto_April23__1___1[[#This Row],[Cereals and products]:[Pan, tobacco and intoxicants]]) -> 1497.7 | AJ13: =SUM(All_India_Index_Upto_April23__1___1[[#This Row],[Household goods and services]],All_India_Index_Upto_April23__1___1[[#This Row],[Housing]]) -> 206.8 | AK13: =All_India_Index_Upto_April23__1___1[[#This Row],[Clothing]]+All_India_Index_Upto_April23__1___1[[#This Row],[Footwear]] -> 215 | AL13: =All_India_Index_Upto_April23__1___1[[#This Row],[Miscellaneous]]+All_India_Index_Upto_April23__1___1[[#This Row],[Personal care and effects]]+All_India_Index_Upto_April23__1___1[[#This Row],[Education]]+All_India_Index_Upto_April23__1___1[[#This Row],[Recreation and amusement]] -> 416.9 | AM13: =SUM(All_India_Index_Upto_April23__1___1[[#This Row],[Sum of others]],All_India_Index_Upto_April23__1___1[[#This Row],[Sum of clothing]],All_India_Index_Upto_April23__1___1[[#This Row],[Sum of Housing Exp]],All_India_Index_Upto_April23__1___1[[#This Row],[Sum of food expenses]],All_India_Index_Upto_April23__1___1[[#This Row],[Transport and communication]],All_India_Index_Upto_April23__1___1[[#This Row],[Health]],All_India_Index_Upto_April23__1___1[[#This Row],[Fuel and light]]) -> 2652.9
A14: Rural | B14: 2013 | C14: May | D14: =TEXT(DATE(B14, MONTH(1&C14), 1), "mmm-yy") -> May-13 | E14: 110.9 | F14: 109.8 | G14: 105.9 | H14: 107.5 | I14: 105.3 | J14: 108.1 | K14: 107.3 | L14: 106.1 | M14: 103.7 | N14: 104 | O14: 107.4 | P14: 109.9 | Q14: 108.1 | R14: 108.1 | S14: 108.8 | T14: 107.9 | U14: 108.6 | V14: ='Handle Missing Value Sheet only'!$F$5 -> 139.27097 | W14: 107.5 | X14: 106.8 | Y14: 105.7 | Z14: 104.1 | AA14: 105 | AB14: 105.5 | AC14: 102.1 | AD14: 104.8 | AE14: 107.2 | AF14: =AVERAGE(All_India_Index_Upto_April23__1___1[[#This Row],[Cereals and products]:[Pan, tobacco and intoxicants]]) -> 107.29286 | AG14: =AVERAGE(All_India_Index_Upto_April23__1___1[[#This Row],[Household goods and services]],All_India_Index_Upto_April23__1___1[[#This Row],[Housing]]) -> 123.03548 | AH14: =AVERAGE(All_India_Index_Upto_April23__1___1[[#This Row],[Miscellaneous]],All_India_Index_Upto_April23__1___1[[#This Row],[Personal care and effects]],All_India_Index_Upto_April23__1___1[[#This Row],[Education]],All_India_Index_Upto_April23__1___1[[#This Row],[Recreation and amusement]]) -> 104.35 | AI14: =SUM(All_India_Index_Upto_April23__1___1[[#This Row],[Cereals and products]:[Pan, tobacco and intoxicants]]) -> 1502.1 | AJ14: =SUM(All_India_Index_Upto_April23__1___1[[#This Row],[Household goods and services]],All_India_Index_Upto_April23__1___1[[#This Row],[Housing]]) -> 246.07097 | AK14: =All_India_Index_Upto_April23__1___1[[#This Row],[Clothing]]+All_India_Index_Upto_April23__1___1[[#This Row],[Footwear]] -> 216.7 | AL14: =All_India_Index_Upto_April23__1___1[[#This Row],[Miscellaneous]]+All_India_Index_Upto_April23__1___1[[#This Row],[Personal care and effects]]+All_India_Index_Upto_April23__1___1[[#This Row],[Education]]+All_India_Index_Upto_April23__1___1[[#This Row],[Recreation and amusement]] -> 417.4 | AM14: =SUM(All_India_Index_Upto_April23__1___1[[#This Row],[Sum of others]],All_India_Index_Upto_April23__1___1[[#This Row],[Sum of clothing]],All_India_Index_Upto_April23__1___1[[#This Row],[Sum of Housing Exp]],All_India_Index_Upto_April23__1___1[[#This Row],[Sum of food expenses]],All_India_Index_Upto_April23__1___1[[#This Row],[Transport and communication]],All_India_Index_Upto_April23__1___1[[#This Row],[Health]],All_India_Index_Upto_April23__1___1[[#This Row],[Fuel and light]]) -> 2699.571
A15: Urban | B15: 2013 | C15: May | D15: =TEXT(DATE(B15, MONTH(1&C15), 1), "mmm-yy") -> May-13 | E15: 115.4 | F15: 114.2 | G15: 102.7 | H15: 105.5 | I15: 101.5 | J15: 110.6 | K15: 123.7 | L15: 105.2 | M15: 101.9 | N15: 105 | O15: 109.1 | P15: 111.3 | Q15: 111.1 | R15: 109.8 | S15: 108.5 | T15: 106.7 | U15: 108.3 | V15: 100.5 | W15: 107.2 | X15: 107.1 | Y15: 106.2 | Z15: 103.9 | AA15: 104.6 | AB15: 105.7 | AC15: 102.6 | AD15: 104.9 | AE15: 106.6 | AF15: =AVERAGE(All_India_Index_Upto_April23__1___1[[#This Row],[Cereals and products]:[Pan, tobacco and intoxicants]]) -> 109.07143 | AG15: =AVERAGE(All_India_Index_Upto_April23__1___1[[#This Row],[Household goods and services]],All_India_Index_Upto_April23__1___1[[#This Row],[Housing]]) -> 103.8 | AH15: =AVERAGE(All_India_Index_Upto_April23__1___1[[#This Row],[Miscellaneous]],All_India_Index_Upto_April23__1___1[[#This Row],[Personal care and effects]],All_India_Index_Upto_April23__1___1[[#This Row],[Education]],All_India_Index_Upto_April23__1___1[[#This Row],[Recreation and amusement]]) -> 104.45 | AI15: =SUM(All_India_Index_Upto_April23__1___1[[#This Row],[Cereals and products]:[Pan, tobacco and intoxicants]]) -> 1527 | AJ15: =SUM(All_India_Index_Upto_April23__1___1[[#This Row],[Household goods and services]],All_India_Index_Upto_April23__1___1[[#This Row],[Housing]]) -> 207.6 | AK15: =All_India_Index_Upto_April23__1___1[[#This Row],[Clothing]]+All_India_Index_Upto_April23__1___1[[#This Row],[Footwear]] -> 215.2 | AL15: =All_India_Index_Upto_April23__1___1[[#This Row],[Miscellaneous]]+All_India_Index_Upto_April23__1___1[[#This Row],[Personal care and effects]]+All_India_Index_Upto_April23__1___1[[#This Row],[Education]]+All_India_Index_Upto_April23__1___1[[#This Row],[Recreation and amusement]] -> 417.8 | AM15: =SUM(All_India_Index_Upto_April23__1___1[[#This Row],[Sum of others]],All_India_Index_Upto_April23__1___1[[#This Row],[Sum of clothing]],All_India_Index_Upto_April23__1___1[[#This Row],[Sum of Housing Exp]],All_India_Index_Upto_April23__1___1[[#This Row],[Sum of food expenses]],All_India_Index_Upto_April23__1___1[[#This Row],[Transport and communication]],All_India_Index_Upto_April23__1___1[[#This Row],[Health]],All_India_Index_Upto_April23__1___1[[#This Row],[Fuel and light]]) -> 2684.9
A16: Rural+Urban | B16: 2013 | C16: May | D16: =TEXT(DATE(B16, MONTH(1&C16), 1), "mmm-yy") -> May-13 | E16: 112.3 | F16: 111.3 | G16: 104.7 | H16: 106.8 | I16: 103.9 | J16: 109.3 | K16: 112.9 | L16: 105.8 | M16: 103.1 | N16: 104.3 | O16: 108.1 | P16: 110.5 | Q16: 109.2 | R16: 108.6 | S16: 108.7 | T16: 107.4 | U16: 108.5 | V16: 100.5 | W16: 107.4 | X16: 106.9 | Y16: 105.9 | Z16: 104 | AA16: 104.8 | AB16: 105.6 | AC16: 102.3 | AD16: 104.8 | AE16: 106.9 | AF16: =AVERAGE(All_India_Index_Upto_April23__1___1[[#This Row],[Cereals and products]:[Pan, tobacco and intoxicants]]) -> 107.91429 | AG16: =AVERAGE(All_India_Index_Upto_April23__1___1[[#This Row],[Household goods and services]],All_India_Index_Upto_April23__1___1[[#This Row],[Housing]]) -> 103.7 | AH16: =AVERAGE(All_India_Index_Upto_April23__1___1[[#This Row],[Miscellaneous]],All_India_Index_Upto_April23__1___1[[#This Row],[Personal care and effects]],All_India_Index_Upto_April23__1___1[[#This Row],[Education]],All_India_Index_Upto_April23__1___1[[#This Row],[Recreation and amusement]]) -> 104.375 | AI16: =SUM(All_India_Index_Upto_April23__1___1[[#This Row],[Cereals and products]:[Pan, tobacco and intoxicants]]) -> 1510.8 | AJ16: =SUM(All_India_Index_Upto_April23__1___1[[#This Row],[Household goods and services]],All_India_Index_Upto_April23__1___1[[#This Row],[Housing]]) -> 207.4 | AK16: =All_India_Index_Upto_April23__1___1[[#This Row],[Clothing]]+All_India_Index_Upto_April23__1___1[[#This Row],[Footwear]] -> 216.1 | AL16: =All_India_Index_Upto_April23__1___1[[#This Row],[Miscellaneous]]+All_India_Index_Upto_April23__1___1[[#This Row],[Personal care and effects]]+All_India_Index_Upto_April23__1___1[[#This Row],[Education]]+All_India_Index_Upto_April23__1___1[[#This Row],[Recreation and amusement]] -> 417.5 | AM16: =SUM(All_India_Index_Upto_April23__1___1[[#This Row],[Sum of others]],All_India_Index_Upto_April23__1___1[[#This Row],[Sum of clothing]],All_India_Index_Upto_April23__1___1[[#This Row],[Sum of Housing Exp]],All_India_Index_Upto_April23__1___1[[#This Row],[Sum of food expenses]],All_India_Index_Upto_April23__1___1[[#This Row],[Transport and communication]],All_India_Index_Upto_April23__1___1[[#This Row],[Health]],All_India_Index_Upto_April23__1___1[[#This Row],[Fuel and light]]) -> 2669.1
A17: Rural | B17: 2013 | C17: June | D17: =TEXT(DATE(B17, MONTH(1&C17), 1), "mmm-yy") -> Jun-13 | E17: 112.3 | F17: 112.1 | G17: 108.1 | H17: 108.3 | I17: 105.9 | J17: 109.2 | K17: 118 | L17: 106.8 | M17: 104.1 | N17: 105.4 | O17: 108.2 | P17: 111 | Q17: 110.6 | R17: 109 | S17: 109.7 | T17: 108.8 | U17: 109.5 | V17: ='Handle Missing Value Sheet only'!$F$5 -> 139.27097 | W17: 108.5 | X17: 107.5 | Y17: 106.3 | Z17: 105 | AA17: 105.6 | AB17: 106.5 | AC17: 102.5 | AD17: 105.5 | AE17: 108.9 | AF17: =AVERAGE(All_India_Index_Upto_April23__1___1[[#This Row],[Cereals and products]:[Pan, tobacco and intoxicants]]) -> 109.21429 | AG17: =AVERAGE(All_India_Index_Upto_April23__1___1[[#This Row],[Household goods and services]],All_India_Index_Upto_April23__1___1[[#This Row],[Housing]]) -> 123.38548 | AH17: =AVERAGE(All_India_Index_Upto_April23__1___1[[#This Row],[Miscellaneous]],All_India_Index_Upto_April23__1___1[[#This Row],[Personal care and effects]],All_India_Index_Upto_April23__1___1[[#This Row],[Education]],All_India_Index_Upto_April23__1___1[[#This Row],[Recreation and amusement]]) -> 105.025 | AI17: =SUM(All_India_Index_Upto_April23__1___1[[#This Row],[Cereals and products]:[Pan, tobacco and intoxicants]]) -> 1529 | AJ17: =SUM(All_India_Index_Upto_April23__1___1[[#This Row],[Household goods and services]],All_India_Index_Upto_April23__1___1[[#This Row],[Housing]]) -> 246.77097 | AK17: =All_India_Index_Upto_April23__1___1[[#This Row],[Clothing]]+All_India_Index_Upto_April23__1___1[[#This Row],[Footwear]] -> 218.5 | AL17: =All_India_Index_Upto_April23__1___1[[#This Row],[Miscellaneous]]+All_India_Index_Upto_April23__1___1[[#This Row],[Personal care and effects]]+All_India_Index_Upto_April23__1___1[[#This Row],[Education]]+All_India_Index_Upto_April23__1___1[[#This Row],[Recreation and amusement]] -> 420.1 | AM17: =SUM(All_India_Index_Upto_April23__1___1[[#This Row],[Sum of others]],All_India_Index_Upto_April23__1___1[[#This Row],[Sum of clothing]],All_India_Index_Upto_April23__1___1[[#This Row],[Sum of Housing Exp]],All_India_Index_Upto_April23__1___1[[#This Row],[Sum of food expenses]],All_India_Index_Upto_April23__1___1[[#This Row],[Transport and communication]],All_India_Index_Upto_April23__1___1[[#This Row],[Health]],All_India_Index_Upto_April23__1___1[[#This Row],[Fuel and light]]) -> 2734.171
A18: Urban | B18: 2013 | C18: June | D18: =TEXT(DATE(B18, MONTH(1&C18), 1), "mmm-yy") -> Jun-13 | E18: 117 | F18: 120.1 | G18: 112.5 | H18: 107.3 | I18: 101.3 | J18: 112.4 | K18: 143.6 | L18: 105.4 | M18: 101.4 | N18: 106.4 | O18: 110 | P18: 112.2 | Q18: 115 | R18: 110.9 | S18: 109.2 | T18: 107.2 | U18: 108.9 | V18: 106.6 | W18: 108 | X18: 107.7 | Y18: 106.5 | Z18: 105.2 | AA18: 105.2 | AB18: 108.1 | AC18: 103.3 | AD18: 106.1 | AE18: 109.7 | AF18: =AVERAGE(All_India_Index_Upto_April23__1___1[[#This Row],[Cereals and products]:[Pan, tobacco and intoxicants]]) -> 112.53571 | AG18: =AVERAGE(All_India_Index_Upto_April23__1___1[[#This Row],[Household goods and services]],All_India_Index_Upto_April23__1___1[[#This Row],[Housing]]) -> 107.15 | AH18: =AVERAGE(All_India_Index_Upto_April23__1___1[[#This Row],[Miscellaneous]],All_India_Index_Upto_April23__1___1[[#This Row],[Personal care and effects]],All_India_Index_Upto_April23__1___1[[#This Row],[Education]],All_India_Index_Upto_April23__1___1[[#This Row],[Recreation and amusement]]) -> 105.675 | AI18: =SUM(All_India_Index_Upto_April23__1___1[[#This Row],[Cereals and products]:[Pan, tobacco and intoxicants]]) -> 1575.5 | AJ18: =SUM(All_India_Index_Upto_April23__1___1[[#This Row],[Household goods and services]],All_India_Index_Upto_April23__1___1[[#This Row],[Housing]]) -> 214.3 | AK18: =All_India_Index_Upto_April23__1___1[[#This Row],[Clothing]]+All_India_Index_Upto_April23__1___1[[#This Row],[Footwear]] -> 216.4 | AL18: =All_India_Index_Upto_April23__1___1[[#This Row],[Miscellaneous]]+All_India_Index_Upto_April23__1___1[[#This Row],[Personal care and effects]]+All_India_Index_Upto_April23__1___1[[#This Row],[Education]]+All_India_Index_Upto_April23__1___1[[#This Row],[Recreation and amusement]] -> 422.7 | AM18: =SUM(All_India_Index_Upto_April23__1___1[[#This Row],[Sum of others]],All_India_Index_Upto_April23__1___1[[#This Row],[Sum of clothing]],All_India_Index_Upto_April23__1___1[[#This Row],[Sum of Housing Exp]],All_India_Index_Upto_April23__1___1[[#This Row],[Sum of food expenses]],All_India_Index_Upto_April23__1___1[[#This Row],[Transport and communication]],All_India_Index_Upto_April23__1___1[[#This Row],[Health]],All_India_Index_Upto_April23__1___1[[#This Row],[Fuel and light]]) -> 2748.6
A19: Rural+Urban | B19: 2013 | C19: June | D19: =TEXT(DATE(B19, MONTH(1&C19), 1), "mmm-yy") -> Jun-13 | E19: 113.8 | F19: 114.9 | G19: 109.8 | H19: 107.9 | I19: 104.2 | J19: 110.7 | K19: 126.7 | L19: 106.3 | M19: 103.2 | N19: 105.7 | O19: 109 | P19: 111.6 | Q19: 112.2 | R19: 109.5 | S19: 109.5 | T19: 108.1 | U19: 109.3 | V19: 106.6 | W19: 108.3 | X19: 107.6 | Y19: 106.4 | Z19: 105.1 | AA19: 105.4 | AB19: 107.4 | AC19: 102.8 | AD19: 105.8 | AE19: 109.3 | AF19: =AVERAGE(All_India_Index_Upto_April23__1___1[[#This Row],[Cereals and products]:[Pan, tobacco and intoxicants]]) -> 110.39286 | AG19: =AVERAGE(All_India_Index_Upto_April23__1___1[[#This Row],[Household goods and services]],All_India_Index_Upto_April23__1___1[[#This Row],[Housing]]) -> 107.1 | AH19: =AVERAGE(All_India_Index_Upto_April23__1___1[[#This Row],[Miscellaneous]],All_India_Index_Upto_April23__1___1[[#This Row],[Personal care and effects]],All_India_Index_Upto_April23__1___1[[#This Row],[Education]],All_India_Index_Upto_April23__1___1[[#This Row],[Recreation and amusement]]) -> 105.35 | AI19: =SUM(All_India_Index_Upto_April23__1___1[[#This Row],[Cereals and products]:[Pan, tobacco and intoxicants]]) -> 1545.5 | AJ19: =SUM(All_India_Index_Upto_April23__1___1[[#This Row],[Household goods and services]],All_India_Index_Upto_April23__1___1[[#This Row],[Housing]]) -> 214.2 | AK19: =All_India_Index_Upto_April23__1___1[[#This Row],[Clothing]]+All_India_Index_Upto_April23__1___1[[#This Row],[Footwear]] -> 217.6 | AL19: =All_India_Index_Upto_April23__1___1[[#This Row],[Miscellaneous]]+All_India_Index_Upto_April23__1___1[[#This Row],[Personal care and effects]]+All_India_Index_Upto_April23__1___1[[#This Row],[Education]]+All_India_Index_Upto_April23__1___1[[#This Row],[Recreation and amusement]] -> 421.4 | AM19: =SUM(All_India_Index_Upto_April23__1___1[[#This Row],[Sum of others]],All_India_Index_Upto_April23__1___1[[#This Row],[Sum of clothing]],All_India_Index_Upto_April23__1___1[[#This Row],[Sum of Housing Exp]],All_India_Index_Upto_April23__1___1[[#This Row],[Sum of food expenses]],All_India_Index_Upto_April23__1___1[[#This Row],[Transport and communication]],All_India_Index_Upto_April23__1___1[[#This Row],[Health]],All_India_Index_Upto_April23__1___1[[#This Row],[Fuel and light]]) -> 2718.5
A20: Rural | B20: 2013 | C20: July | D20: =TEXT(DATE(B20, MONTH(1&C20), 1), "mmm-yy") -> Jul-13 | E20: 113.4 | F20: 114.9 | G20: 110.5 | H20: 109.3 | I20: 106.2 | J20: 110.3 | K20: 129.2 | L20: 107.1 | M20: 104.3 | N20: 106.4 | O20: 109.1 | P20: 112.1 | Q20: 113.1 | R20: 109.8 | S20: 110.5 | T20: 109.5 | U20: 110.3 | V20: ='Handle Missing Value Sheet only'!$F$5 -> 139.27097 | W20: 109.5 | X20: 108.3 | Y20: 106.9 | Z20: 106.8 | AA20: 106.4 | AB20: 107.8 | AC20: 102.5 | AD20: 106.5 | AE20: 110.7 | AF20: =AVERAGE(All_India_Index_Upto_April23__1___1[[#This Row],[Cereals and products]:[Pan, tobacco and intoxicants]]) -> 111.12143 | AG20: =AVERAGE(All_India_Index_Upto_April23__1___1[[#This Row],[Household goods and services]],All_India_Index_Upto_April23__1___1[[#This Row],[Housing]]) -> 123.78548 | AH20: =AVERAGE(All_India_Index_Upto_April23__1___1[[#This Row],[Miscellaneous]],All_India_Index_Upto_April23__1___1[[#This Row],[Personal care and effects]],All_India_Index_Upto_April23__1___1[[#This Row],[Education]],All_India_Index_Upto_April23__1___1[[#This Row],[Recreation and amusement]]) -> 105.8 | AI20: =SUM(All_India_Index_Upto_April23__1___1[[#This Row],[Cereals and products]:[Pan, tobacco and intoxicants]]) -> 1555.7 | AJ20: =SUM(All_India_Index_Upto_April23__1___1[[#This Row],[Household goods and services]],All_India_Index_Upto_April23__1___1[[#This Row],[Housing]]) -> 247.57097 | AK20: =All_India_Index_Upto_April23__1___1[[#This Row],[Clothing]]+All_India_Index_Upto_April23__1___1[[#This Row],[Footwear]] -> 220 | AL20: =All_India_Index_Upto_April23__1___1[[#This Row],[Miscellaneous]]+All_India_Index_Upto_April23__1___1[[#This Row],[Personal care and effects]]+All_India_Index_Upto_April23__1___1[[#This Row],[Education]]+All_India_Index_Upto_April23__1___1[[#This Row],[Recreation and amusement]] -> 423.2 | AM20: =SUM(All_India_Index_Upto_April23__1___1[[#This Row],[Sum of others]],All_India_Index_Upto_April23__1___1[[#This Row],[Sum of clothing]],All_India_Index_Upto_April23__1___1[[#This Row],[Sum of Housing Exp]],All_India_Index_Upto_April23__1___1[[#This Row],[Sum of food expenses]],All_India_Index_Upto_April23__1___1[[#This Row],[Transport and communication]],All_India_Index_Upto_April23__1___1[[#This Row],[Health]],All_India_Index_Upto_April23__1___1[[#This Row],[Fuel and light]]) -> 2769.671
A21: Urban | B21: 2013 | C21: July | D21: =TEXT(DATE(B21, MONTH(1&C21), 1), "mmm-yy") -> Jul-13 | E21: 117.8 | F21: 119.2 | G21: 114 | H21: 108.3 | I21: 101.1 | J21: 113.2 | K21: 160.9 | L21: 105.1 | M21: 101.3 | N21: 107.5 | O21: 110.4 | P21: 113.1 | Q21: 117.5 | R21: 111.7 | S21: 109.8 | T21: 107.8 | U21: 109.5 | V21: 107.7 | W21: 108.6 | X21: 108.1 | Y21: 107.1 | Z21: 107.3 | AA21: 105.9 | AB21: 110.1 | AC21: 103.2 | AD21: 107.3 | AE21: 111.4 | AF21: =AVERAGE(All_India_Index_Upto_April23__1___1[[#This Row],[Cereals and products]:[Pan, tobacco and intoxicants]]) -> 114.36429 | AG21: =AVERAGE(All_India_Index_Upto_April23__1___1[[#This Row],[Household goods and services]],All_India_Index_Upto_April23__1___1[[#This Row],[Housing]]) -> 107.9 | AH21: =AVERAGE(All_India_Index_Upto_April23__1___1[[#This Row],[Miscellaneous]],All_India_Index_Upto_April23__1___1[[#This Row],[Personal care and effects]],All_India_Index_Upto_April23__1___1[[#This Row],[Education]],All_India_Index_Upto_April23__1___1[[#This Row],[Recreation and amusement]]) -> 106.625 | AI21: =SUM(All_India_Index_Upto_April23__1___1[[#This Row],[Cereals and products]:[Pan, tobacco and intoxicants]]) -> 1601.1 | AJ21: =SUM(All_India_Index_Upto_April23__1___1[[#This Row],[Household goods and services]],All_India_Index_Upto_April23__1___1[[#This Row],[Housing]]) -> 215.8 | AK21: =All_India_Index_Upto_April23__1___1[[#This Row],[Clothing]]+All_India_Index_Upto_April23__1___1[[#This Row],[Footwear]] -> 217.6 | AL21: =All_India_Index_Upto_April23__1___1[[#This Row],[Miscellaneous]]+All_India_Index_Upto_April23__1___1[[#This Row],[Personal care and effects]]+All_India_Index_Upto_April23__1___1[[#This Row],[Education]]+All_India_Index_Upto_April23__1___1[[#This Row],[Recreation and amusement]] -> 426.5 | AM21: =SUM(All_India_Index_Upto_April23__1___1[[#This Row],[Sum of others]],All_India_Index_Upto_April23__1___1[[#This Row],[Sum of clothing]],All_India_Index_Upto_April23__1___1[[#This Row],[Sum of Housing Exp]],All_India_Index_Upto_April23__1___1[[#This Row],[Sum of food expenses]],All_India_Index_Upto_April23__1___1[[#This Row],[Transport and communication]],All_India_Index_Upto_April23__1___1[[#This Row],[Health]],All_India_Index_Upto_April23__1___1[[#This Row],[Fuel and light]]) -> 2784
A22: Rural+Urban | B22: 2013 | C22: July | D22: =TEXT(DATE(B22, MONTH(1&C22), 1), "mmm-yy") -> Jul-13 | E22: 114.8 | F22: 116.4 | G22: 111.9 | H22: 108.9 | I22: 104.3 | J22: 111.7 | K22: 140 | L22: 106.4 | M22: 103.3 | N22: 106.8 | O22: 109.6 | P22: 112.6 | Q22: 114.7 | R22: 110.3 | S22: 110.2 | T22: 108.8 | U22: 110 | V22: 107.7 | W22: 109.2 | X22: 108.2 | Y22: 107 | Z22: 107.1 | AA22: 106.1 | AB22: 109.1 | AC22: 102.8 | AD22: 106.9 | AE22: 111 | AF22: =AVERAGE(All_India_Index_Upto_April23__1___1[[#This Row],[Cereals and products]:[Pan, tobacco and intoxicants]]) -> 112.26429 | AG22: =AVERAGE(All_India_Index_Upto_April23__1___1[[#This Row],[Household goods and services]],All_India_Index_Upto_April23__1___1[[#This Row],[Housing]]) -> 107.95 | AH22: =AVERAGE(All_India_Index_Upto_April23__1___1[[#This Row],[Miscellaneous]],All_India_Index_Upto_April23__1___1[[#This Row],[Personal care and effects]],All_India_Index_Upto_April23__1___1[[#This Row],[Education]],All_India_Index_Upto_April23__1___1[[#This Row],[Recreation and amusement]]) -> 106.225 | AI22: =SUM(All_India_Index_Upto_April23__1___1[[#This Row],[Cereals and products]:[Pan, tobacco and intoxicants]]) -> 1571.7 | AJ22: =SUM(All_India_Index_Upto_April23__1___1[[#This Row],[Household goods and services]],All_India_Index_Upto_April23__1___1[[#This Row],[Housing]]) -> 215.9 | AK22: =All_India_Index_Upto_April23__1___1[[#This Row],[Clothing]]+All_India_Index_Upto_April23__1___1[[#This Row],[Footwear]] -> 219 | AL22: =All_India_Index_Upto_April23__1___1[[#This Row],[Miscellaneous]]+All_India_Index_Upto_April23__1___1[[#This Row],[Personal care and effects]]+All_India_Index_Upto_April23__1___1[[#This Row],[Education]]+All_India_Index_Upto_April23__1___1[[#This Row],[Recreation and amusement]] -> 424.9 | AM22: =SUM(All_India_Index_Upto_April23__1___1[[#This Row],[Sum of others]],All_India_Index_Upto_April23__1___1[[#This Row],[Sum of clothing]],All_India_Index_Upto_April23__1___1[[#This Row],[Sum of Housing Exp]],All_India_Index_Upto_April23__1___1[[#This Row],[Sum of food expenses]],All_India_Index_Upto_April23__1___1[[#This Row],[Transport and communication]],All_India_Index_Upto_April23__1___1[[#This Row],[Health]],All_India_Index_Upto_April23__1___1[[#This Row],[Fuel and light]]) -> 2754.8
A23: Rural | B23: 2013 | C23: August | D23: =TEXT(DATE(B23, MONTH(1&C23), 1), "mmm-yy") -> Aug-13 | E23: 114.3 | F23: 115.4 | G23: 111.1 | H23: 110 | I23: 106.4 | J23: 110.8 | K23: 138.9 | L23: 107.4 | M23: 104.1 | N23: 106.9 | O23: 109.7 | P23: 112.6 | Q23: 114.9 | R23: 110.7 | S23: 111.3 | T23: 110.2 | U23: 111.1 | V23: ='Handle Missing Value Sheet only'!$F$5 -> 139.27097 | W23: 109.9 | X23: 108.7 | Y23: 107.5 | Z23: 107.8 | AA23: 106.8 | AB23: 108.7 | AC23: 105 | AD23: 107.5 | AE23: 112.1 | AF23: =AVERAGE(All_India_Index_Upto_April23__1___1[[#This Row],[Cereals and products]:[Pan, tobacco and intoxicants]]) -> 112.37143 | AG23: =AVERAGE(All_India_Index_Upto_April23__1___1[[#This Row],[Household goods and services]],All_India_Index_Upto_April23__1___1[[#This Row],[Housing]]) -> 123.98548 | AH23: =AVERAGE(All_India_Index_Upto_April23__1___1[[#This Row],[Miscellaneous]],All_India_Index_Upto_April23__1___1[[#This Row],[Personal care and effects]],All_India_Index_Upto_April23__1___1[[#This Row],[Education]],All_India_Index_Upto_April23__1___1[[#This Row],[Recreation and amusement]]) -> 107 | AI23: =SUM(All_India_Index_Upto_April23__1___1[[#This Row],[Cereals and products]:[Pan, tobacco and intoxicants]]) -> 1573.2 | AJ23: =SUM(All_India_Index_Upto_April23__1___1[[#This Row],[Household goods and services]],All_India_Index_Upto_April23__1___1[[#This Row],[Housing]]) -> 247.97097 | AK23: =All_India_Index_Upto_April23__1___1[[#This Row],[Clothing]]+All_India_Index_Upto_April23__1___1[[#This Row],[Footwear]] -> 221.5 | AL23: =All_India_Index_Upto_April23__1___1[[#This Row],[Miscellaneous]]+All_India_Index_Upto_April23__1___1[[#This Row],[Personal care and effects]]+All_India_Index_Upto_April23__1___1[[#This Row],[Education]]+All_India_Index_Upto_April23__1___1[[#This Row],[Recreation and amusement]] -> 428 | AM23: =SUM(All_India_Index_Upto_April23__1___1[[#This Row],[Sum of others]],All_India_Index_Upto_April23__1___1[[#This Row],[Sum of clothing]],All_India_Index_Upto_April23__1___1[[#This Row],[Sum of Housing Exp]],All_India_Index_Upto_April23__1___1[[#This Row],[Sum of food expenses]],All_India_Index_Upto_April23__1___1[[#This Row],[Transport and communication]],All_India_Index_Upto_April23__1___1[[#This Row],[Health]],All_India_Index_Upto_April23__1___1[[#This Row],[Fuel and light]]) -> 2795.871
A24: Urban | B24: 2013 | C24: August | D24: =TEXT(DATE(B24, MONTH(1&C24), 1), "mmm-yy") -> Aug-13 | E24: 118.3 | F24: 120.4 | G24: 112.7 | H24: 108.9 | I24: 101.1 | J24: 108.7 | K24: 177 | L24: 104.7 | M24: 101 | N24: 108.5 | O24: 110.9 | P24: 114.3 | Q24: 119.6 | R24: 112.4 | S24: 110.6 | T24: 108.3 | U24: 110.2 | V24: 108.9 | W24: 109.3 | X24: 108.7 | Y24: 107.6 | Z24: 108.1 | AA24: 106.5 | AB24: 110.8 | AC24: 106 | AD24: 108.3 | AE24: 112.7 | AF24: =AVERAGE(All_India_Index_Upto_April23__1___1[[#This Row],[Cereals and products]:[Pan, tobacco and intoxicants]]) -> 115.60714 | AG24: =AVERAGE(All_India_Index_Upto_April23__1___1[[#This Row],[Household goods and services]],All_India_Index_Upto_April23__1___1[[#This Row],[Housing]]) -> 108.8 | AH24: =AVERAGE(All_India_Index_Upto_April23__1___1[[#This Row],[Miscellaneous]],All_India_Index_Upto_April23__1___1[[#This Row],[Personal care and effects]],All_India_Index_Upto_April23__1___1[[#This Row],[Education]],All_India_Index_Upto_April23__1___1[[#This Row],[Recreation and amusement]]) -> 107.9 | AI24: =SUM(All_India_Index_Upto_April23__1___1[[#This Row],[Cereals and products]:[Pan, tobacco and intoxicants]]) -> 1618.5 | AJ24: =SUM(All_India_Index_Upto_April23__1___1[[#This Row],[Household goods and services]],All_India_Index_Upto_April23__1___1[[#This Row],[Housing]]) -> 217.6 | AK24: =All_India_Index_Upto_April23__1___1[[#This Row],[Clothing]]+All_India_Index_Upto_April23__1___1[[#This Row],[Footwear]] -> 218.9 | AL24: =All_India_Index_Upto_April23__1___1[[#This Row],[Miscellaneous]]+All_India_Index_Upto_April23__1___1[[#This Row],[Personal care and effects]]+All_India_Index_Upto_April23__1___1[[#This Row],[Education]]+All_India_Index_Upto_April23__1___1[[#This Row],[Recreation and amusement]] -> 431.6 | AM24: =SUM(All_India_Index_Upto_April23__1___1[[#This Row],[Sum of others]],All_India_Index_Upto_April23__1___1[[#This Row],[Sum of clothing]],All_India_Index_Upto_April23__1___1[[#This Row],[Sum of Housing Exp]],All_India_Index_Upto_April23__1___1[[#This Row],[Sum of food expenses]],All_India_Index_Upto_April23__1___1[[#This Row],[Transport and communication]],All_India_Index_Upto_April23__1___1[[#This Row],[Health]],All_India_Index_Upto_April23__1___1[[#This Row],[Fuel and light]]) -> 2811.6
A25: Rural+Urban | B25: 2013 | C25: August | D25: =TEXT(DATE(B25, MONTH(1&C25), 1), "mmm-yy") -> Aug-13 | E25: 115.6 | F25: 117.2 | G25: 111.7 | H25: 109.6 | I25: 104.5 | J25: 109.8 | K25: 151.8 | L25: 106.5 | M25: 103.1 | N25: 107.4 | O25: 110.2 | P25: 113.4 | Q25: 116.6 | R25: 111.2 | S25: 111 | T25: 109.4 | U25: 110.7 | V25: 108.9 | W25: 109.7 | X25: 108.7 | Y25: 107.5 | Z25: 108 | AA25: 106.6 | AB25: 109.9 | AC25: 105.4 | AD25: 107.9 | AE25: 112.4 | AF25: =AVERAGE(All_India_Index_Upto_April23__1___1[[#This Row],[Cereals and products]:[Pan, tobacco and intoxicants]]) -> 113.47143 | AG25: =AVERAGE(All_India_Index_Upto_April23__1___1[[#This Row],[Household goods and services]],All_India_Index_Upto_April23__1___1[[#This Row],[Housing]]) -> 108.8 | AH25: =AVERAGE(All_India_Index_Upto_April23__1___1[[#This Row],[Miscellaneous]],All_India_Index_Upto_April23__1___1[[#This Row],[Personal care and effects]],All_India_Index_Upto_April23__1___1[[#This Row],[Education]],All_India_Index_Upto_April23__1___1[[#This Row],[Recreation and amusement]]) -> 107.45 | AI25: =SUM(All_India_Index_Upto_April23__1___1[[#This Row],[Cereals and products]:[Pan, tobacco and intoxicants]]) -> 1588.6 | AJ25: =SUM(All_India_Index_Upto_April23__1___1[[#This Row],[Household goods and services]],All_India_Index_Upto_April23__1___1[[#This Row],[Housing]]) -> 217.6 | AK25: =All_India_Index_Upto_April23__1___1[[#This Row],[Clothing]]+All_India_Index_Upto_April23__1___1[[#This Row],[Footwear]] -> 220.4 | AL25: =All_India_Index_Upto_April23__1___1[[#This Row],[Miscellaneous]]+All_India_Index_Upto_April23__1___1[[#This Row],[Personal care and effects]]+All_India_Index_Upto_April23__1___1[[#This Row],[Education]]+All_India_Index_Upto_April23__1___1[[#This Row],[Recreation and amusement]] -> 429.8 | AM25: =SUM(All_India_Index_Upto_April23__1___1[[#This Row],[Sum of others]],All_India_Index_Upto_April23__1___1[[#This Row],[Sum of clothing]],All_India_Index_Upto_April23__1___1[[#This Row],[Sum of Housing Exp]],All_India_Index_Upto_April23__1___1[[#This Row],[Sum of food expenses]],All_India_Index_Upto_April23__1___1[[#This Row],[Transport and communication]],All_India_Index_Upto_April23__1___1[[#This Row],[Health]],All_India_Index_Upto_April23__1___1[[#This Row],[Fuel and light]]) -> 2781.6
A26: Rural | B26: 2013 | C26: September | D26: =TEXT(DATE(B26, MONTH(1&C26), 1), "mmm-yy") -> Sep-13 | E26: 115.4 | F26: 115.7 | G26: 111.7 | H26: 111 | I26: 107.4 | J26: 110.9 | K26: 154 | L26: 108.1 | M26: 104.2 | N26: 107.9 | O26: 110.4 | P26: 114 | Q26: 117.8 | R26: 111.7 | S26: 112.7 | T26: 111.4 | U26: 112.5 | V26: ='Handle Missing Value Sheet only'!$F$5 -> 139.27097 | W26: 111.1 | X26: 109.6 | Y26: 108.3 | Z26: 109.3 | AA26: 107.7 | AB26: 109.8 | AC26: 106.7 | AD26: 108.7 | AE26: 114.2 | AF26: =AVERAGE(All_India_Index_Upto_April23__1___1[[#This Row],[Cereals and products]:[Pan, tobacco and intoxicants]]) -> 114.3 | AG26: =AVERAGE(All_India_Index_Upto_April23__1___1[[#This Row],[Household goods and services]],All_India_Index_Upto_April23__1___1[[#This Row],[Housing]]) -> 124.43548 | AH26: =AVERAGE(All_India_Index_Upto_April23__1___1[[#This Row],[Miscellaneous]],All_India_Index_Upto_April23__1___1[[#This Row],[Personal care and effects]],All_India_Index_Upto_April23__1___1[[#This Row],[Education]],All_India_Index_Upto_April23__1___1[[#This Row],[Recreation and amusement]]) -> 108.225 | AI26: =SUM(All_India_Index_Upto_April23__1___1[[#This Row],[Cereals and products]:[Pan, tobacco and intoxicants]]) -> 1600.2 | AJ26: =SUM(All_India_Index_Upto_April23__1___1[[#This Row],[Household goods and services]],All_India_Index_Upto_April23__1___1[[#This Row],[Housing]]) -> 248.87097 | AK26: =All_India_Index_Upto_April23__1___1[[#This Row],[Clothing]]+All_India_Index_Upto_April23__1___1[[#This Row],[Footwear]] -> 224.1 | AL26: =All_India_Index_Upto_April23__1___1[[#This Row],[Miscellaneous]]+All_India_Index_Upto_April23__1___1[[#This Row],[Personal care and effects]]+All_India_Index_Upto_April23__1___1[[#This Row],[Education]]+All_India_Index_Upto_April23__1___1[[#This Row],[Recreation and amusement]] -> 432.9 | AM26: =SUM(All_India_Index_Upto_April23__1___1[[#This Row],[Sum of others]],All_India_Index_Upto_April23__1___1[[#This Row],[Sum of clothing]],All_India_Index_Upto_April23__1___1[[#This Row],[Sum of Housing Exp]],All_India_Index_Upto_April23__1___1[[#This Row],[Sum of food expenses]],All_India_Index_Upto_April23__1___1[[#This Row],[Transport and communication]],All_India_Index_Upto_April23__1___1[[#This Row],[Health]],All_India_Index_Upto_April23__1___1[[#This Row],[Fuel and light]]) -> 2834.771
